Workbook

Sheet Calculations
B3: Scenario | C3: CO2 emissions [kg] | D3: Bill from supplier [DKK] | E3: Cost of PV | F3: Cost of wind turbine | G3: Cost of PV and wind turbine [DKK] | H3: Total costs [DKK] (Incl. revenue from wind) | I3: Revenue from wind [DKK] | J3: Total revenue [DKK] | K3: Revenue - costs [DKK] | L3: Electricity consumed [kWh] | M3: Electricity produced by PV [kWh] | N3: Electricity produced by wind turbine [kWh] | O3: Electricity bought from grid [kWh] | P3: Electricity bought from peer-to-peer [kWh] | Q3: Electricity sold to grid [kWh]
B4: Base case | C4: 118388.99 | D4: 717929.97 | E4: 42357.88 | G4: =E4+F4 -> 42357.88 | H4: =D4+G4-I4 -> 760287.85 | L4: 455079.99
B5: Scenario 1 | C5: 157208.03 | D5: 816834.58 | G5: =E5+F5 -> 0 | H5: =D5+G5-I5 -> 816834.58 | L5: 455079.99 | M5: 123079.98
B6: Scenario 2 | C6: 118426.62 | D6: 619590.9 | E6: 42357.88 | G6: =E6+F6 -> 42357.88 | H6: =D6+G6-I6 -> 661948.78 | L6: 455079.99 | M6: 123079.98 | O6: 332115.16 | P6: 66955.008
B7: Scenario 3 | C7: -10611.195 | D7: 356645.98 | E7: 183135.54 | G7: =E7+F7 -> 183135.54 | H7: =D7+G7-I7 -> 539781.52 | L7: 455079.99 | M7: 532139.9 | O7: -77007.711 | P7: 4538.017
B8: Scenario 4 | C8: 64316.094 | D8: 412566.66 | E8: 42357.88 | F8: 142672.5 | G8: =E8+F8 -> 185030.38 | H8: =D8+G8-I8 -> 590828.17 | I8: 6768.871 | L8: 455079.99 | M8: 123079.98 | N8: 230112.92
B9: Scenario 5 | C9: -76363.171 | D9: 144949.78 | E9: 183135.54 | F9: 142672.5 | G9: =E9+F9 -> 325808.04 | H9: =D9+G9-I9 -> 447764.76 | I9: 22993.057 | L9: 455079.99 | M9: 532139.9 | N9: 230112.92
B11: =27/137 -> 0.19708029 | E11: =(E9+F9)/E9 -> 1.7790541
B12: =B3 -> Scenario | C12: =C3 -> CO2 emissions [kg] | E12: =B3 -> Scenario | F12: Bill from supplier | G12: =E3 -> Cost of PV | H12: =F3 -> Cost of wind turbine | I12: CO2 emissions [kg]
B13: =B4 -> Base case | C13: =C4 -> 118388.99 | D13: =C13/$C$14 -> 0.75307215 | E13: =B4 -> Base case | F13: =D4-I4 -> 717929.97 | G13: =E4 -> 42357.88 | H13: =F4 -> 0 | I13: =C4 -> 118388.99 | J13: =(F13+G13+H13)/$F$14 -> 0.93077335
B14: =B5 -> Scenario 1 | C14: =C5 -> 157208.03 | D14: =C14/$C$14 -> 1 | E14: =B5 -> Scenario 1 | F14: =D5-I5 -> 816834.58 | G14: =E5 -> 0 | H14: =F5 -> 0 | I14: =C5 -> 157208.03 | J14: =(F14+G14+H14)/$F$14 -> 1
B15: =B6 -> Scenario 2 | C15: =C6 -> 118426.62 | D15: =C15/$C$14 -> 0.75331154 | E15: =B6 -> Scenario 2 | F15: =D6-I6 -> 619590.9 | G15: =E6 -> 42357.88 | H15: =F6 -> 0 | I15: =C6 -> 118426.62 | J15: =(F15+G15+H15)/$F$14 -> 0.81038291
B16: =B7 -> Scenario 3 | C16: =C7 -> -10611.195 | D16: =C16/$C$14 -> -0.067497796 | E16: =B7 -> Scenario 3 | F16: =D7-I7 -> 356645.98 | G16: =E7 -> 183135.54 | H16: =F7 -> 0 | I16: =C7 -> -10611.195 | J16: =(F16+G16+H16)/$F$14 -> 0.6608211
B17: =B8 -> Scenario 4 | C17: =C8 -> 64316.094 | D17: =C17/$C$14 -> 0.40911456 | E17: =B8 -> Scenario 4 | F17: =D8-I8 -> 405797.79 | G17: =E8 -> 42357.88 | H17: =F8 -> 142672.5 | I17: =C8 -> 64316.094 | J17: =(F17+G17+H17)/$F$14 -> 0.72331435
B18: =B9 -> Scenario 5 | C18: =C9 -> -76363.171 | D18: =C18/$C$14 -> -0.485746 | E18: =B9 -> Scenario 5 | F18: =D9-I9 -> 121956.72 | G18: =E9 -> 183135.54 | H18: =F9 -> 142672.5 | I18: =C9 -> -76363.171 | J18: =(F18+G18+H18)/$F$14 -> 0.54817068 | O18: 676.221 | P18: 2009.296 | R18: 3312.392 | S18: 5565.669 | T18: 6204.392
H20: Scenario
H21: Base case | I21: =(H$4-(H$4-H4))/(H$4) -> 1 | J21: =H$4-H4 -> 0 | K21: =C4 -> 118388.99 | N21: Self-sufficiency | O21: Base Scenario | P21: Scenario 1 | Q21: Scenario 2 | R21: Scenario 3 | S21: Scenario 4 | T21: Scenario 5
H22: Scenario 1 | I22: =(H$4-(H$4-H5))/(H$4) -> 1.0743754 | J22: =H$4-H5 -> -56546.723 | K22: =C5 -> 157208.03 | L22: =(K$21-(K$21-K22))/(K$21) -> 1.327894 | N22: -0.2 | O22: 634 | P22: 0 | Q22: 1759 | R22: 3154 | S22: 5438 | T22: 6129
H23: Scenario 2 | I23: =(H$4-(H$4-H6))/(H$4) -> 0.87065547 | J23: =H$4-H6 -> 98339.073 | K23: =C6 -> 118426.62 | L23: =(K$21-(K$21-K23))/(K$21) -> 1.0003179 | N23: Base | O23: 676 | P23: 0 | Q23: 2009 | R23: 3312 | S23: 5565 | T23: 6204
H24: Scenario 3 | I24: =(H$4-(H$4-H7))/(H$4) -> 0.70996994 | J24: =H$4-H7 -> 220506.33 | K24: =C7 -> -10611.195 | L24: =(K$21-(K$21-K24))/(K$21) -> -0.089629919 | N24: 0.2 | O24: 707 | P24: 0 | Q24: 2204 | R24: 3430 | S24: 5664 | T24: 6261
H25: Scenario 4 | I25: =(H$4-(H$4-H8))/(H$4) -> 0.77711115 | J25: =H$4-H8 -> 169459.68 | K25: =C8 -> 64316.094 | L25: =(K$21-(K$21-K25))/(K$21) -> 0.54326077 | N25: -0.2 | O25: =O22/8760*100 -> 7.2374429 | P25: =P22/8760*100 -> 0 | Q25: =Q22/8760*100 -> 20.079909 | R25: =R22/8760*100 -> 36.004566 | S25: =S22/8760*100 -> 62.077626 | T25: =T22/8760*100 -> 69.965753
H26: Scenario 5 | I26: =(H$4-(H$4-H9))/(H$4) -> 0.5889411 | J26: =H$4-H9 -> 312523.09 | K26: =C9 -> -76363.171 | L26: =(K$21-(K$21-K26))/(K$21) -> -0.6450192 | N26: % base | O26: =O23/8760*100 -> 7.716895 | P26: =P23/8760*100 -> 0 | Q26: =Q23/8760*100 -> 22.93379 | R26: =R23/8760*100 -> 37.808219 | S26: =S23/8760*100 -> 63.527397 | T26: =T23/8760*100 -> 70.821918
N27: 0.2 | O27: =O24/8760*100 -> 8.0707763 | P27: =P24/8760*100 -> 0 | Q27: =Q24/8760*100 -> 25.159817 | R27: =R24/8760*100 -> 39.155251 | S27: =S24/8760*100 -> 64.657534 | T27: =T24/8760*100 -> 71.472603
N28: Diff | O28: =O25-O26 -> -0.47945205 | P28: =P25-P26 -> 0 | Q28: =Q25-Q26 -> -2.8538813 | R28: =R25-R26 -> -1.803653 | S28: =S25-S26 -> -1.4497717 | T28: =T25-T26 -> -0.85616438
I29: Scenario | J29: Solar production | K29: WT production | L29: Self-suffiency | N29: Diff | O29: =O26-O26 -> 0 | P29: =P26-P26 -> 0 | Q29: =Q26-Q26 -> 0 | R29: =R26-R26 -> 0 | S29: =S26-S26 -> 0 | T29: =T26-T26 -> 0
I30: Base case | L30: =D6/D4*L32 -> 0.23260459 | M30: 456745.19 | N30: Diff | O30: =O27-O26 -> 0.35388128 | P30: =P27-P26 -> 0 | Q30: =Q27-Q26 -> 2.2260274 | R30: =R27-R26 -> 1.347032 | S30: =S27-S26 -> 1.130137 | T30: =T27-T26 -> 0.65068493
I31: Scenario 1 | J31: 0 | M31: 456745.19 | N31: Diff | O31: =O22-O23 -> -42 | P31: =P22-P23 -> 0 | Q31: =Q22-Q23 -> -250 | R31: =R22-R23 -> -158 | S31: =S22-S23 -> -127 | T31: =T22-T23 -> -75
I32: Scenario 2 | J32: 123103.19 | L32: =J32/M32 -> 0.26952269 | M32: 456745.19 | N32: Diff | O32: =O23-O23 -> 0 | P32: =P23-P23 -> 0 | Q32: =Q23-Q23 -> 0 | R32: =R23-R23 -> 0 | S32: =S23-S23 -> 0 | T32: =T23-T23 -> 0
I33: Scenario 3 | J33: 532240.26 | L33: =J33/M33 -> 1.1652893 | M33: 456745.19 | N33: Diff | O33: =O24-O23 -> 31 | P33: =P24-P23 -> 0 | Q33: =Q24-Q23 -> 195 | R33: =R24-R23 -> 118 | S33: =S24-S23 -> 99 | T33: =T24-T23 -> 57
I34: Scenario 4 | J34: =J32 -> 123103.19 | K34: =J34*K36 -> 8789.1156 | L34: =(J34+K34)/M34 -> 0.28876562 | M34: 456745.19
I35: Scenario 5 | J35: =J33 -> 532240.26 | K35: =38000 -> 38000 | L35: =(J35+K35)/M35 -> 1.2484866 | M35: 456745.19
K36: =K35/J35 -> 0.071396327
J37: =J35+K35 -> 570240.26
B40: Total cost | C40: For sensitivity
E44: =G47/E47 -> 0.82952962
B45: Base Scenario | C45: Scenario 1 | D45: Scenario 2 | E45: Scenario 3 | F45: Scenario 4 | G45: Scenario 5 | J45: Base Scenario | K45: Scenario 1 | L45: Scenario 2 | M45: Scenario 3 | N45: Scenario 4 | O45: Scenario 5
A46: -0.2 | B46: =D62 -> 772932.15 | C46: =C47 -> 816834.58 | D46: =K77 -> 690905.75 | E46: =K83 -> 592785.56 | F46: =J86 -> 609831.81 | G46: =J95 -> 518216.52 | I46: -0.2 | J46: =Q71 -> 126686.64 | L46: =Q77 -> 126191.78 | M46: =Q83 -> 22955.771 | N46: =N47+(N47-N48) -> 72240.006 | O46: =S95 -> -41638.706
A47: Base | B47: =F13+G13+H13 -> 760287.85 | C47: =F14+G14+H14 -> 816834.58 | D47: =F15+G15+H15 -> 661948.78 | E47: =F16+G16+H16 -> 539781.52 | F47: =F17+G17+H17 -> 590828.17 | G47: =F18+G18+H18 -> 447764.76 | I47: Base | J47: =C4 -> 118388.99 | K47: =C5 -> 157208.03 | L47: =C6 -> 118426.62 | M47: =C7 -> -10611.195 | N47: =C8 -> 64316.094 | O47: =C9 -> -76363.171
A48: 0.2 | B48: =B47-(B46-B47) -> 747643.55 | C48: =C47 -> 816834.58 | D48: =K74 -> 636736.64 | E48: =K80 -> 490105.1 | F48: =O89 -> 586038.9 | G48: =J92 -> 425257.51 | I48: 0.2 | J48: =J47-(J46-J47) -> 110091.34 | L48: =Q74 -> 110661.74 | M48: =Q80 -> -44178.38 | N48: =S89 -> 56392.182 | O48: =S92 -> -110872.67
A49: Diff -20 | B49: =B46-B47 -> 12644.3 | C49: =$B$46-C46 -> -43902.423 | D49: =$B$46-D46 -> 82026.403 | E49: =$B$46-E46 -> 180146.59 | F49: =$B$46-F46 -> 163100.34 | G49: =$B$46-G46 -> 254715.64
...

Sheet Overview
C1: ✔ | D1: ✔ | E1: ✔ | H1: ✔
C2: Total bill [DKK] | D2: Total PV cost [DKK] | E2: Total wind turbine cost [DKK] | F2: PV production | G2: Wind production | H2: CO2 emissions [kg] | I2: El purchased | J2: El from PtoP | K2: El from grid | L2: El consumption | P2: Base | Q2: Scenario 1 | R2: Scenario 2 | S2: Scenario 3 | T2: Scenario 4 | U2: Scenario 5
B3: Base case | C3: ='Basecase updated1'!O102 -> 717929.97 | D3: ='Basecase updated1'!P102 -> 42357.88 | H3: ='Basecase updated1'!W102 -> 118388.99 | O3: Own PV | Q3: 0 | R3: =C13 -> 56009.818 | S3: =D13 -> 450541.97
B4: Scenario 1 | C4: ='Scenario 1 Updated'!Q103 -> 816834.58 | H4: ='Scenario 1 Updated'!V103 -> 157208.03 | O4: Peer-to-peer | Q4: 0 | R4: =C14 -> 66955.008 | S4: =D14 -> 4538.017
B5: Scenario 2 | C5: 619590.9 | D5: 42357.88 | F5: ='Scenario 2 Updated'!D103 -> 123079.98 | H5: 118426.62 | J5: 66955.008 | K5: 332115.16 | L5: 455079.99 | O5: Grid | Q5: =L6 -> 455079.99 | R5: =C15 -> 332115.16 | S5: =D15 -> -77007.711
B6: Scenario 3 | C6: 356645.98 | D6: 183135.54 | F6: 532139.9 | H6: -10611.195 | I6: -77059.918 | J6: 4538.017 | K6: -77007.711 | L6: 455079.99
B7: Scenario 4 | C7: 412566.66 | D7: 42357.88 | E7: 142672.5 | G7: 230112.92 | H7: 64316.094 | P7: Statistics on 137 agents:
B8: Scenario 5 | C8: 144949.78 | D8: 183135.54 | E8: 142672.5 | G8: 230112.92 | H8: -76363.171 | P8: communityTotalBillPeerToPeer: 4,206.19
P9: communityHourlyCO2: 24.473
J10: =J5+K5 -> 399070.17 | L10: =J6/L6 -> 0.0099719107 | P10: communityTotalCO2: -10,137.416
P11: communityTotalSolarCost: 183,637.281
C12: Scenario 2 | D12: Scenario 3 | P12: communityTotalElFromSupplier: -75,442.681
B13: Own PV | C13: =L5-K5-J5 -> 56009.818 | D13: =L6-J6 -> 450541.97 | E13: =D13+D14-D15 -> 532087.7 | F13: Solar (27 households with PV) | G13: =F5 -> 123079.98 | P13: communityTotalElPurchased: -75,495.078
B14: Peer-to-peer | C14: =J5 -> 66955.008 | D14: =J6 -> 4538.017 | F14: Solar (137 households with PV) | G14: =F6 -> 532139.9 | J14: =F5+K5 -> 455195.14 | P14: communityHourlyElPurchased: 63.17
B15: Grid | C15: =K5 -> 332115.16 | D15: =K6 -> -77007.711 | F15: Wind | G15: =G7 -> 230112.92 | P15: communityHourlyElConsumption: 63.17
P16: communityTotalElConsumption: 456,745.186
P17: communityHourlySolarProduction: 0
P18: communityTotalBillSupplier: 358,415.213
P19: communityHourlyElFromPeerToPeer: 0
P20: communityTotalSolarProduction: 532,240.264
P21: communityTotalRevenue: 147,869.802
P22: communityHourlyElFromSupplier: 63.17
P23: communityTotalElFromPeerToPeer: 4,538.24
H35: 102 kW | J35: 441 kW | L35: 90 kW

Sheet Old Calculations
B3: Scenario | C3: CO2 emissions [kg] | D3: Bill from supplier [DKK] | E3: Cost of PV | F3: Cost of wind turbine | G3: Cost of PV and wind turbine [DKK] | H3: Total costs [DKK] | I3: Revenue from wind [DKK] | J3: Total revenue [DKK] | K3: Revenue - costs [DKK] | L3: Electricity consumed [kWh] | M3: Electricity produced by PV [kWh] | N3: Electricity produced by wind turbine [kWh] | O3: Electricity bought from grid [kWh] | P3: Electricity bought from peer-to-peer [kWh] | Q3: Electricity sold to grid [kWh]
B4: Base case | C4: ='Base case'!M102 -> 118882.61 | D4: ='Base case'!G102 -> 719792.62 | E4: ='Base case'!H102 -> 42473.929 | F4: 0 | G4: ='Base case'!H102 -> 42473.929 | H4: =D4+G4 -> 762266.55 | J4: ='Base case'!C104 -> 32044.59 | L4: 456745.19
B5: Scenario 1 | C5: ='Scenario 1'!M102 -> 157707.63 | D5: ='Scenario 1'!H102 -> 818723.99 | E5: ='Scenario 1'!I102 -> 0 | F5: 0 | G5: 0 | H5: =D5+G5 -> 818723.99 | J5: =0 -> 0 | L5: 456745.19 | M5: 123103.19
B6: Scenario 2 | C6: ='Scenario 2'!W102 -> 118920.28 | D6: ='Scenario 2'!O102 -> 621452.62 | E6: ='Scenario 2'!P102 -> 42473.929 | F6: 0 | G6: ='Scenario 2'!P102 -> 42473.929 | H6: =D6+G6 -> 663926.55 | J6: ='Scenario 2'!T102 -> 68988.081 | L6: 456745.19 | M6: 123103.19 | O6: 333757.34 | P6: 66955.897
B7: Scenario 3 | C7: ='Scenario 3'!$X$102 -> -10137.416 | D7: ='Scenario 3'!O102 -> 358415.21 | E7: ='Scenario 3'!P102 -> 183637.28 | F7: 0 | G7: ='Scenario 3'!P102 -> 183637.28 | H7: =D7+G7 -> 542052.49 | J7: ='Scenario 3'!T102 -> 147869.8 | L7: 456745.19 | M7: 532240.26 | O7: -75442.681
B8: Scenario 4 | C8: ='Scenario 4'!$R$102 -> 64552.081 | D8: ='Scenario 4'!$L$102 -> 413532.49 | E8: ='Scenario 4'!$M$102 -> 42473.929 | F8: ='Scenario 4'!$O$102 -> 143063.38 | G8: ='Scenario 4'!$M$102+'Scenario 4'!$O$102 -> 185537.31 | H8: =D8+G8 -> 599069.81 | I8: ='Scenario 4'!$G$102 -> 6789.1656 | J8: ='Scenario 4'!$G$102+'Scenario 4'!$H$102 -> 41452.912 | L8: 456745.19 | M8: 123103.19
B9: Scenario 5 | C9: ='Scenario 5'!$V$102 -> -76149.035 | D9: ='Scenario 5'!$N$102 -> 145823.48 | E9: ='Scenario 5'!$O$102 -> 183637.28 | F9: ='Scenario 5'!$Q$102 -> 143063.38 | G9: ='Scenario 5'!$O$102+'Scenario 5'!$Q$102 -> 326700.66 | H9: =D9+G9 -> 472524.15 | I9: ='Scenario 5'!$H$102 -> 23013.351 | J9: ='Scenario 5'!$H$102+'Scenario 5'!$I$102 -> 178226.54 | L9: 456745.19 | M9: 532240.26
B11: =27/137 -> 0.19708029
B12: =B3 -> Scenario | C12: =C3 -> CO2 emissions [kg] | E12: =B3 -> Scenario | F12: Bill from supplier | G12: =E3 -> Cost of PV | H12: =F3 -> Cost of wind turbine | I12: CO2 emissions [kg]
B13: =B4 -> Base case | C13: =C4 -> 118882.61 | D13: =C13/$C$14 -> 0.75381647 | E13: =B4 -> Base case | F13: =D4-I4 -> 719792.62 | G13: =E4 -> 42473.929 | H13: =F4 -> 0 | I13: 118882.61 | J13: =(F13+G13+H13)/$F$14 -> 0.93104216
B14: =B5 -> Scenario 1 | C14: =C5 -> 157707.63 | D14: =C14/$C$14 -> 1 | E14: =B5 -> Scenario 1 | F14: =D5-I5 -> 818723.99 | G14: =E5 -> 0 | H14: =F5 -> 0 | I14: 157707.63 | J14: =(F14+G14+H14)/$F$14 -> 1
B15: =B6 -> Scenario 2 | C15: =C6 -> 118920.28 | D15: =C15/$C$14 -> 0.75405533 | E15: =B6 -> Scenario 2 | F15: =D6-I6 -> 621452.62 | G15: =E6 -> 42473.929 | H15: =F6 -> 0 | I15: 118920.28 | J15: =(F15+G15+H15)/$F$14 -> 0.81092842
B16: =B7 -> Scenario 3 | C16: =C7 -> -10137.416 | D16: =C16/$C$14 -> -0.064279807 | E16: =B7 -> Scenario 3 | F16: =D7-I7 -> 358415.21 | G16: =E7 -> 183637.28 | H16: =F7 -> 0 | I16: -10137.416 | J16: =(F16+G16+H16)/$F$14 -> 0.66206988
B17: =B8 -> Scenario 4 | C17: =C8 -> 64552.081 | D17: =C17/$C$14 -> 0.40931489 | E17: =B8 -> Scenario 4 | F17: =D8-I8 -> 406743.33 | G17: =E8 -> 42473.929 | H17: =F8 -> 143063.38 | I17: 64552.081 | J17: =(F17+G17+H17)/$F$14 -> 0.72341918
B18: =B9 -> Scenario 5 | C18: =C9 -> -76149.035 | D18: =C18/$C$14 -> -0.4828494 | E18: =B9 -> Scenario 5 | F18: =D9-I9 -> 122810.13 | G18: =E9 -> 183637.28 | H18: =F9 -> 143063.38 | I18: -76149.035 | J18: =(F18+G18+H18)/$F$14 -> 0.54903826 | O18: 676.221 | P18: 2009.296 | R18: 3312.392 | S18: 5565.669 | T18: 6204.392
H20: Scenario
H21: Base case | I21: =(H$4-(H$4-H4))/(H$4) -> 1 | J21: =H$4-H4 -> 0 | K21: =C4 -> 118882.61 | N21: Self-suff | O21: Base Scenario | P21: Scenario 1 | Q21: Scenario 2 | R21: Scenario 3 | S21: Scenario 4 | T21: Scenario 5
H22: Scenario 1 | I22: =(H$4-(H$4-H5))/(H$4) -> 1.0740652 | J22: =H$4-H5 -> -56457.442 | K22: =C5 -> 157707.63 | L22: =(K$21-(K$21-K22))/(K$21) -> 1.3265829 | N22: -0.2 | O22: 634 | P22: 0 | Q22: 1759 | R22: 3154 | S22: 5438 | T22: 6129
H23: Scenario 2 | I23: =(H$4-(H$4-H6))/(H$4) -> 0.87099001 | J23: =H$4-H6 -> 98340 | K23: =C6 -> 118920.28 | L23: =(K$21-(K$21-K23))/(K$21) -> 1.0003169 | N23: Base | O23: 676 | P23: 0 | Q23: 2009 | R23: 3312 | S23: 5565 | T23: 6204
H24: Scenario 3 | I24: =(H$4-(H$4-H7))/(H$4) -> 0.71110623 | J24: =H$4-H7 -> 220214.06 | K24: =C7 -> -10137.416 | L24: =(K$21-(K$21-K24))/(K$21) -> -0.08527249 | N24: 0.2 | O24: 707 | P24: 0 | Q24: 2204 | R24: 3430 | S24: 5664 | T24: 6261
H25: Scenario 4 | I25: =(H$4-(H$4-H8))/(H$4) -> 0.78590594 | J25: =H$4-H8 -> 163196.74 | K25: =C8 -> 64552.081 | L25: =(K$21-(K$21-K25))/(K$21) -> 0.54299011 | N25: -0.2 | O25: =O22/8760*100 -> 7.2374429 | P25: =P22/8760*100 -> 0 | Q25: =Q22/8760*100 -> 20.079909 | R25: =R22/8760*100 -> 36.004566 | S25: =S22/8760*100 -> 62.077626 | T25: =T22/8760*100 -> 69.965753
H26: Scenario 5 | I26: =(H$4-(H$4-H9))/(H$4) -> 0.61989359 | J26: =H$4-H9 -> 289742.4 | K26: =C9 -> -76149.035 | L26: =(K$21-(K$21-K26))/(K$21) -> -0.64053974 | N26: % base | O26: =O23/8760*100 -> 7.716895 | P26: =P23/8760*100 -> 0 | Q26: =Q23/8760*100 -> 22.93379 | R26: =R23/8760*100 -> 37.808219 | S26: =S23/8760*100 -> 63.527397 | T26: =T23/8760*100 -> 70.821918
N27: 0.2 | O27: =O24/8760*100 -> 8.0707763 | P27: =P24/8760*100 -> 0 | Q27: =Q24/8760*100 -> 25.159817 | R27: =R24/8760*100 -> 39.155251 | S27: =S24/8760*100 -> 64.657534 | T27: =T24/8760*100 -> 71.472603
N28: Diff | O28: =O25-O26 -> -0.47945205 | P28: =P25-P26 -> 0 | Q28: =Q25-Q26 -> -2.8538813 | R28: =R25-R26 -> -1.803653 | S28: =S25-S26 -> -1.4497717 | T28: =T25-T26 -> -0.85616438
I29: Scenario | J29: Solar production | K29: WT production | L29: Self-suffiency | N29: Diff | O29: =O26-O26 -> 0 | P29: =P26-P26 -> 0 | Q29: =Q26-Q26 -> 0 | R29: =R26-R26 -> 0 | S29: =S26-S26 -> 0 | T29: =T26-T26 -> 0
I30: Base case | L30: =D6/D4*L32 -> 0.23269977 | M30: 456745.19 | N30: Diff | O30: =O27-O26 -> 0.35388128 | P30: =P27-P26 -> 0 | Q30: =Q27-Q26 -> 2.2260274 | R30: =R27-R26 -> 1.347032 | S30: =S27-S26 -> 1.130137 | T30: =T27-T26 -> 0.65068493
I31: Scenario 1 | J31: 0 | M31: 456745.19 | N31: Diff | O31: =O22-O23 -> -42 | P31: =P22-P23 -> 0 | Q31: =Q22-Q23 -> -250 | R31: =R22-R23 -> -158 | S31: =S22-S23 -> -127 | T31: =T22-T23 -> -75
I32: Scenario 2 | J32: 123103.19 | L32: =J32/M32 -> 0.26952269 | M32: 456745.19 | N32: Diff | O32: =O23-O23 -> 0 | P32: =P23-P23 -> 0 | Q32: =Q23-Q23 -> 0 | R32: =R23-R23 -> 0 | S32: =S23-S23 -> 0 | T32: =T23-T23 -> 0
I33: Scenario 3 | J33: 532240.26 | L33: =J33/M33 -> 1.1652893 | M33: 456745.19 | N33: Diff | O33: =O24-O23 -> 31 | P33: =P24-P23 -> 0 | Q33: =Q24-Q23 -> 195 | R33: =R24-R23 -> 118 | S33: =S24-S23 -> 99 | T33: =T24-T23 -> 57
I34: Scenario 4 | J34: =J32 -> 123103.19 | K34: =J34*K36 -> 8789.1156 | L34: =(J34+K34)/M34 -> 0.28876562 | M34: 456745.19
I35: Scenario 5 | J35: =J33 -> 532240.26 | K35: =38000 -> 38000 | L35: =(J35+K35)/M35 -> 1.2484866 | M35: 456745.19
K36: =K35/J35 -> 0.071396327
J37: =J35+K35 -> 570240.26
B40: Total cost | C40: For sensitivity
B45: Base Scenario | C45: Scenario 1 | D45: Scenario 2 | E45: Scenario 3 | F45: Scenario 4 | G45: Scenario 5 | J45: Base Scenario | K45: Scenario 1 | L45: Scenario 2 | M45: Scenario 3 | N45: Scenario 4 | O45: Scenario 5
A46: -0.2 | B46: =D62 -> 772932.15 | C46: =C47 -> 818723.99 | D46: =K77 -> 690905.75 | E46: =K83 -> 592785.56 | F46: =J86 -> 609831.81 | G46: =J95 -> 518216.52 | I46: -0.2 | J46: =Q71 -> 126686.64 | L46: =Q77 -> 126191.78 | M46: =Q83 -> 22955.771 | N46: =N47+(N47-N48) -> 72711.98 | O46: =S95 -> -41638.706
A47: Base | B47: =F13+G13+H13 -> 762266.55 | C47: =F14+G14+H14 -> 818723.99 | D47: =F15+G15+H15 -> 663926.55 | E47: =F16+G16+H16 -> 542052.49 | F47: =F17+G17+H17 -> 592280.64 | G47: =F18+G18+H18 -> 449510.8 | I47: Base | J47: =C4 -> 118882.61 | K47: =C5 -> 157707.63 | L47: =C6 -> 118920.28 | M47: =C7 -> -10137.416 | N47: =C8 -> 64552.081 | O47: =C9 -> -76149.035
A48: 0.2 | B48: =B47-(B46-B47) -> 751600.95 | C48: =C47 -> 818723.99 | D48: =K74 -> 636736.64 | E48: =K80 -> 490105.1 | F48: =O89 -> 586038.9 | G48: =J92 -> 425257.51 | I48: 0.2 | J48: =J47-(J46-J47) -> 111078.58 | L48: =Q74 -> 110661.74 | M48: =Q80 -> -44178.38 | N48: =S89 -> 56392.182 | O48: =S92 -> -110872.67
A49: Diff -20 | B49: =B46-B47 -> 10665.603 | C49: =$B$46-C46 -> -45791.839 | D49: =$B$46-D46 -> 82026.403 | E49: =$B$46-E46 -> 180146.59 | F49: =$B$46-F46 -> 163100.34 | G49: =$B$46-G46 -> 254715.64
A50: Diff base | B50: =$B$47-B47 -> 0 | C50: =$B$47-C47 -> -56457.442 | D50: =$B$47-D47 -> 98340 | E50: =$B$47-E47 -> 220214.06 | F50: =$B$47-F47 -> 169985.91 | G50: =$B$47-G47 -> 312755.75
...

Sheet Base case
C2: Cumulative lost revenue [DKK] | G2: Cumulative bill [DKK] | H2: Cumulative PV cost [DKK] | I2: Cumulative total costs [DKK] | M2: Cumulative CO2 emissions [kg] | O2: Statistics on 137 agents: | AA2: totalBill | AB2: lostRevenue | AC2: totalCO2 | AD2: totalCostPV | AE2: totalElConsumption
B3: 8684.004 | C3: 48056.249 | F3: 8684.004 | G3: 712409.84 | H3: 41995.227 | I3: 754405.07 | L3: 8684.004 | M3: 117183.98 | O3: communityTotalBill: 719,792.62 | Z3: Consumer 1 | AA3: 6016.743 | AB3: 3220.966 | AC3: -139.823 | AD3: 2914.877 | AE3: 7324.43
B4: 8685.004 | C4: 48056.249 | F4: 8685.004 | G4: 712491.5 | H4: 42000.062 | I4: 754491.56 | L4: 8685.004 | M4: 117197.64 | O4: communityTotalCO2: 118,882.608 | Z4: Consumer 2 | AA4: 2814.307 | AB4: 1359.271 | AC4: -2.326 | AD4: 1249.233 | AE4: 3219.89
B5: 8686.004 | C5: 48056.249 | F5: 8686.004 | G5: 712558.37 | H5: 42004.898 | I5: 754563.27 | L5: 8686.004 | M5: 117209.18 | O5: communityHourlyCO2: 24.473 | Z5: Consumer 3 | AA5: 4044.091 | AB5: 1886.331 | AC5: 32.271 | AD5: 1665.644
B6: 8687.004 | C6: 48056.249 | F6: 8687.004 | G6: 712611.1 | H6: 42009.733 | I6: 754620.83 | L6: 8687.004 | M6: 117221.36 | O6: communityTotalSolarCost: 42,473.929 | Z6: Consumer 4
B7: 8688.004 | C7: 48056.249 | F7: 8688.004 | G7: 712659.57 | H7: 42014.568 | I7: 754674.14 | L7: 8688.004 | M7: 117234.53 | O7: communityHourlySolarProduction: 0 | Z7: Consumer 5
B8: 8689.004 | C8: 48056.249 | F8: 8689.004 | G8: 712701.84 | H8: 42019.404 | I8: 754721.25 | L8: 8689.004 | M8: 117246.48 | O8: communityHourlyElPurchased: 63.17 | Z8: Consumer 6
B9: 8690.004 | C9: 48056.249 | F9: 8690.004 | G9: 712740.15 | H9: 42024.239 | I9: 754764.39 | L9: 8690.004 | M9: 117257.46 | O9: communityHourlyElConsumption: 63.17 | Z9: Consumer 7
B10: 8691.004 | C10: 48056.249 | F10: 8691.004 | G10: 712777.23 | H10: 42029.075 | I10: 754806.3 | L10: 8691.004 | M10: 117269.61 | O10: communityTotalLostRevenue: 48,066.885 | Z10: Consumer 8
B11: 8692.004 | C11: 48056.249 | F11: 8692.004 | G11: 712814.24 | H11: 42033.91 | I11: 754848.15 | L11: 8692.004 | M11: 117282.64 | O11: communityTotalElConsumption: 456,745.186 | Z11: Consumer 9
B12: 8693.004 | C12: 48056.249 | F12: 8693.004 | G12: 712856.31 | H12: 42038.745 | I12: 754895.05 | L12: 8693.004 | M12: 117297.14 | O12: Objects: | Z12: Consumer 10
B13: 8694.004 | C13: 48056.249 | F13: 8694.004 | G13: 712913.45 | H13: 42043.581 | I13: 754957.03 | L13: 8694.004 | M13: 117318.63 | O13: 0: root.community.consumers[0] | Z13: Consumer 11
B14: 8695.004 | C14: 48056.249 | F14: 8695.004 | G14: 712985.62 | H14: 42048.416 | I14: 755034.04 | L14: 8695.004 | M14: 117347.63 | O14: 1: root.community.consumers[1] | Z14: Consumer 12
B15: 8696.004 | C15: 48056.249 | F15: 8696.004 | G15: 713069.23 | H15: 42053.251 | I15: 755122.48 | L15: 8696.004 | M15: 117380.97 | O15: 2: root.community.consumers[2] | Z15: Consumer 13
B16: 8697.004 | C16: 48056.302 | F16: 8697.004 | G16: 713176.75 | H16: 42058.087 | I16: 755234.83 | L16: 8697.004 | M16: 117420.63 | O16: 3: root.community.consumers[3] | Z16: Consumer 14
B17: 8698.004 | C17: 48058.197 | F17: 8698.004 | G17: 713283.17 | H17: 42062.922 | I17: 755346.09 | L17: 8698.004 | M17: 117456.66 | O17: 4: root.community.consumers[4] | Z17: Consumer 15
... B23: 8704.004 | C23: 48066.205 | F23: 8704.004 | G23: 713821.05 | H23: 42091.934 | I23: 755912.98 | L23: 8704.004 | M23: 117624.67 | O23: ... | Z23: Consumer 21
B24: 8705.004 | C24: 48066.205 | F24: 8705.004 | G24: 713975.41 | H24: 42096.77 | I24: 756072.18 | L24: 8705.004 | M24: 117659.95 | Z24: Consumer 22
B25: 8706.004 | C25: 48066.205 | F25: 8706.004 | G25: 714134.17 | H25: 42101.605 | I25: 756235.78 | L25: 8706.004 | M25: 117690.96 | Z25: Consumer 23
B26: 8707.004 | C26: 48066.205 | F26: 8707.004 | G26: 714252.01 | H26: 42106.441 | I26: 756358.45 | L26: 8707.004 | M26: 117712.65 | Z26: Consumer 24
B27: 8708.004 | C27: 48066.205 | F27: 8708.004 | G27: 714338.03 | H27: 42111.276 | I27: 756449.3 | L27: 8708.004 | M27: 117729.61 | Z27: Consumer 25
B28: 8709.004 | C28: 48066.205 | F28: 8709.004 | G28: 714407.05 | H28: 42116.111 | I28: 756523.16 | L28: 8709.004 | M28: 117743.02 | Z28: Consumer 26
B29: 8710.004 | C29: 48066.205 | F29: 8710.004 | G29: 714468.45 | H29: 42120.947 | I29: 756589.4 | L29: 8710.004 | M29: 117754.29 | Z29: Consumer 27
B30: 8711.004 | C30: 48066.205 | F30: 8711.004 | G30: 714517.18 | H30: 42125.782 | I30: 756642.96 | L30: 8711.004 | M30: 117763.22 | Z30: Consumer 28
B31: 8712.004 | C31: 48066.205 | F31: 8712.004 | G31: 714563.88 | H31: 42130.617 | I31: 756694.49 | L31: 8712.004 | M31: 117769.99 | Z31: Consumer 29
B32: 8713.004 | C32: 48066.205 | F32: 8713.004 | G32: 714601.58 | H32: 42135.453 | I32: 756737.03 | L32: 8713.004 | M32: 117774.95 | Z32: Consumer 30
B33: 8714.004 | C33: 48066.205 | F33: 8714.004 | G33: 714637.61 | H33: 42140.288 | I33: 756777.9 | L33: 8714.004 | M33: 117779.91 | Z33: Consumer 31
B34: 8715.004 | C34: 48066.205 | F34: 8715.004 | G34: 714670.41 | H34: 42145.124 | I34: 756815.53 | L34: 8715.004 | M34: 117785.05 | Z34: Consumer 32
B35: 8716.004 | C35: 48066.205 | F35: 8716.004 | G35: 714702.88 | H35: 42149.959 | I35: 756852.84 | L35: 8716.004 | M35: 117789.45 | Z35: Consumer 33
... B102: 8783.004 | C102: 48066.885 | F102: 8783.004 | G102: 719792.62 | H102: 42473.929 | I102: 762266.55 | L102: 8783.004 | M102: 118882.61 | Z102: Consumer 100
Z103: Consumer 101
C104: =C102/3*2 -> 32044.59 | Z104: Consumer 102
Z105: Consumer 103
Z106: Consumer 104
Z107: Consumer 105
Z108: Consumer 106
Z109: Consumer 107
Z110: Consumer 108
Z111: Consumer 109
Z112: Consumer 110
...

Sheet Base -20%
A2: ="-20% solar production" -> -20% solar production | H2: Cumulative bill [DKK] | I2: Cumulative PV cost [DKK] | J2: Cumulative total costs [DKK] | M2: Cumulative CO2 emissions [kg]
G3: 8702.004 | H3: 726237.25 | I3: 42082.264 | J3: 768319.51 | L3: 8702.004 | M3: 125330.46
G4: 8703.004 | H4: 726330.16 | I4: 42087.099 | J4: 768417.26 | L4: 8703.004 | M4: 125356.81
D5: =H3/812443.718019131 -> 0.89389238 | G5: 8704.004 | H5: 726452.42 | I5: 42091.935 | J5: 768544.36 | L5: 8704.004 | M5: 125386.18
G6: 8705.004 | H6: 726606.78 | I6: 42096.77 | J6: 768703.56 | L6: 8705.004 | M6: 125421.46
G7: 8706.004 | H7: 726765.55 | I7: 42101.605 | J7: 768867.15 | L7: 8706.004 | M7: 125452.47
G8: 8707.004 | H8: 726883.38 | I8: 42106.441 | J8: 768989.82 | L8: 8707.004 | M8: 125474.16
G9: 8708.004 | H9: 726969.4 | I9: 42111.276 | J9: 769080.68 | L9: 8708.004 | M9: 125491.12
G10: 8709.004 | H10: 727038.43 | I10: 42116.112 | J10: 769154.54 | L10: 8709.004 | M10: 125504.53
G11: 8710.004 | H11: 727099.83 | I11: 42120.947 | J11: 769220.78 | L11: 8710.004 | M11: 125515.8
G12: 8711.004 | H12: 727148.56 | I12: 42125.782 | J12: 769274.34 | L12: 8711.004 | M12: 125524.73
G13: 8712.004 | H13: 727195.25 | I13: 42130.618 | J13: 769325.87 | L13: 8712.004 | M13: 125531.5
G14: 8713.004 | H14: 727232.96 | I14: 42135.453 | J14: 769368.41 | L14: 8713.004 | M14: 125536.47
G15: 8714.004 | H15: 727268.99 | I15: 42140.288 | J15: 769409.28 | L15: 8714.004 | M15: 125541.43
G16: 8715.004 | H16: 727301.79 | I16: 42145.124 | J16: 769446.91 | L16: 8715.004 | M16: 125546.56
G17: 8716.004 | H17: 727334.26 | I17: 42149.959 | J17: 769484.22 | L17: 8716.004 | M17: 125550.96
... G102: 8801.004 | H102: 733619.55 | I102: 42560.966 | J102: 776180.51 | L102: 8801.004 | M102: 126647.61

Sheet Scenario 1
B2: Statistics on 137 agents: | H2: Cumulative bill [DKK] | I2: Cumulative PV cost [DKK] | J2: Cumulative total costs [DKK] | M2: Cumulative CO2 emissions [kg]
B3: communityHourlySolarProduction: 0 | G3: 8684.004 | H3: 811165.15 | I3: 0 | J3: 811165.15 | L3: 8684.004 | M3: 155950.3
B4: communityHourlyElConsumption: 63.17 | G4: 8685.004 | H4: 811246.8 | I4: 0 | J4: 811246.8 | L4: 8685.004 | M4: 155963.97
B5: communityTotalSolarCost: 0 | G5: 8686.004 | H5: 811313.67 | I5: 0 | J5: 811313.67 | L5: 8686.004 | M5: 155975.51
B6: communityHourlyElPurchased: 63.17 | G6: 8687.004 | H6: 811366.4 | I6: 0 | J6: 811366.4 | L6: 8687.004 | M6: 155987.68
B7: communityTotalLostRevenue: 0 | G7: 8688.004 | H7: 811414.87 | I7: 0 | J7: 811414.87 | L7: 8688.004 | M7: 156000.86
B8: communityTotalElConsumption: 456,745.186 | G8: 8689.004 | H8: 811457.14 | I8: 0 | J8: 811457.14 | L8: 8689.004 | M8: 156012.81
B9: communityHourlyCO2: 24.473 | G9: 8690.004 | H9: 811495.45 | I9: 0 | J9: 811495.45 | L9: 8690.004 | M9: 156023.79
B10: communityTotalBill: 818,723.991 | G10: 8691.004 | H10: 811532.53 | I10: 0 | J10: 811532.53 | L10: 8691.004 | M10: 156035.94
B11: communityTotalCO2: 157,707.63 | G11: 8692.004 | H11: 811569.54 | I11: 0 | J11: 811569.54 | L11: 8692.004 | M11: 156048.97
B12: Objects: | G12: 8693.004 | H12: 811611.61 | I12: 0 | J12: 811611.61 | L12: 8693.004 | M12: 156063.47
B13: 0: root.community.consumers[0] | G13: 8694.004 | H13: 811668.75 | I13: 0 | J13: 811668.75 | L13: 8694.004 | M13: 156084.96
B14: 1: root.community.consumers[1] | G14: 8695.004 | H14: 811740.92 | I14: 0 | J14: 811740.92 | L14: 8695.004 | M14: 156113.96
... B23: ... | G23: 8704.004 | H23: 812659.43 | I23: 0 | J23: 812659.43 | L23: 8704.004 | M23: 156432.22
G24: 8705.004 | H24: 812813.79 | I24: 0 | J24: 812813.79 | L24: 8705.004 | M24: 156467.51
G25: 8706.004 | H25: 812972.56 | I25: 0 | J25: 812972.56 | L25: 8706.004 | M25: 156498.52
G26: 8707.004 | H26: 813090.39 | I26: 0 | J26: 813090.39 | L26: 8707.004 | M26: 156520.21
G27: 8708.004 | H27: 813176.41 | I27: 0 | J27: 813176.41 | L27: 8708.004 | M27: 156537.17
G28: 8709.004 | H28: 813245.44 | I28: 0 | J28: 813245.44 | L28: 8709.004 | M28: 156550.57
G29: 8710.004 | H29: 813306.84 | I29: 0 | J29: 813306.84 | L29: 8710.004 | M29: 156561.85
G30: 8711.004 | H30: 813355.57 | I30: 0 | J30: 813355.57 | L30: 8711.004 | M30: 156570.78
G31: 8712.004 | H31: 813402.26 | I31: 0 | J31: 813402.26 | L31: 8712.004 | M31: 156577.54
G32: 8713.004 | H32: 813439.96 | I32: 0 | J32: 813439.96 | L32: 8713.004 | M32: 156582.51
G33: 8714.004 | H33: 813475.99 | I33: 0 | J33: 813475.99 | L33: 8714.004 | M33: 156587.47
G34: 8715.004 | H34: 813508.79 | I34: 0 | J34: 813508.79 | L34: 8715.004 | M34: 156592.6
G35: 8716.004 | H35: 813541.27 | I35: 0 | J35: 813541.27 | L35: 8716.004 | M35: 156597.01
... G102: 8783.004 | H102: 818723.99 | I102: 0 | J102: 818723.99 | L102: 8783.004 | M102: 157707.63

Sheet Scenario 1 +20%

Sheet Scenario 2
B2: Statistics on 137 agents: | H2: Cumulative solar production [kWh] | I2: Cumulative electricity purchased [kWh] | J2: Cumulative electricity consumption [kWh] | K2: Cumulative electricity from grid [kWh] | L2: Cumulative electricity Peer-to-Peer [kWh] | O2: Cumulative bill supplier [DKK] | P2: Cumulative PV cost [DKK] | Q2: Cumulative total costs [DKK] | T2: Cumulative revenue [DKK] | W2: Cumulative CO2 emissions [kg]
B3: communityTotalElConsumption: 456,745.186 | G3: 8684.006 | H3: 122954.13 | I3: 327432.32 | J3: 450386.45 | K3: 327547.09 | L3: 66935.474 | N3: 8684.006 | O3: 614097.67 | P3: 41995.227 | Q3: 656092.9 | S3: 8684.006 | T3: 68970.356 | V3: 8684.006 | W3: 117221.54
B4: communityTotalSolarCost: 42,473.929 | G4: 8685.006 | H4: 122954.13 | I4: 327507.91 | J4: 450462.04 | K4: 327622.68 | L4: 66935.474 | N4: 8685.006 | O4: 614179.32 | P4: 42000.062 | Q4: 656179.38 | S4: 8685.006 | T4: 68970.356 | V4: 8685.006 | W4: 117235.2
B5: communityTotalRevenue: 68,988.081 | G5: 8686.006 | H5: 122954.13 | I5: 327571.94 | J5: 450526.07 | K5: 327686.71 | L5: 66935.474 | N5: 8686.006 | O5: 614246.2 | P5: 42004.898 | Q5: 656251.09 | S5: 8686.006 | T5: 68970.356 | V5: 8686.006 | W5: 117246.74
B6: communityTotalBillSupplier: 621,452.62 | G6: 8687.006 | H6: 122954.13 | I6: 327623.12 | J6: 450577.25 | K6: 327738.08 | L6: 66935.474 | N6: 8687.006 | O6: 614299.12 | P6: 42009.733 | Q6: 656308.85 | S6: 8687.006 | T6: 68970.356 | V6: 8687.006 | W6: 117258.96
B7: communityTotalElFromSupplier: 333,757.338 | G7: 8688.006 | H7: 122954.13 | I7: 327665.26 | J7: 450619.39 | K7: 327780.22 | L7: 66935.474 | N7: 8688.006 | O7: 614347.59 | P7: 42014.568 | Q7: 656362.16 | S7: 8688.006 | T7: 68970.356 | V7: 8688.006 | W7: 117272.14
B8: communityTotalElFromPeerToPeer: 66,955.897 | G8: 8689.006 | H8: 122954.13 | I8: 327702.03 | J8: 450656.16 | K8: 327816.99 | L8: 66935.474 | N8: 8689.006 | O8: 614389.86 | P8: 42019.404 | Q8: 656409.27 | S8: 8689.006 | T8: 68970.356 | V8: 8689.006 | W8: 117284.09
B9: communityHourlyElFromSupplier: 63.17 | G9: 8690.006 | H9: 122954.13 | I9: 327735.18 | J9: 450689.31 | K9: 327850.14 | L9: 66935.474 | N9: 8690.006 | O9: 614428.17 | P9: 42024.239 | Q9: 656452.41 | S9: 8690.006 | T9: 68970.356 | V9: 8690.006 | W9: 117295.07
B10: communityHourlyElPurchased: 63.17 | G10: 8691.006 | H10: 122954.13 | I10: 327766.98 | J10: 450721.11 | K10: 327881.94 | L10: 66935.474 | N10: 8691.006 | O10: 614465.25 | P10: 42029.075 | Q10: 656494.32 | S10: 8691.006 | T10: 68970.356 | V10: 8691.006 | W10: 117307.22
B11: communityTotalSolarProduction: 123,103.19 | G11: 8692.006 | H11: 122954.13 | I11: 327796.92 | J11: 450751.05 | K11: 327911.88 | L11: 66935.474 | N11: 8692.006 | O11: 614502.26 | P11: 42033.91 | Q11: 656536.17 | S11: 8692.006 | T11: 68970.356 | V11: 8692.006 | W11: 117320.24
B12: communityHourlyElFromPeerToPeer: 0 | G12: 8693.006 | H12: 122954.13 | I12: 327828.78 | J12: 450782.91 | K12: 327943.74 | L12: 66935.474 | N12: 8693.006 | O12: 614544.33 | P12: 42038.745 | Q12: 656583.07 | S12: 8693.006 | T12: 68970.356 | V12: 8693.006 | W12: 117334.75
B13: communityTotalElPurchased: 333,641.996 | G13: 8694.006 | H13: 122954.13 | I13: 327870.66 | J13: 450824.79 | K13: 327985.62 | L13: 66935.474 | N13: 8694.006 | O13: 614601.47 | P13: 42043.581 | Q13: 656645.05 | S13: 8694.006 | T13: 68970.356 | V13: 8694.006 | W13: 117356.23
B14: communityHourlyElConsumption: 63.17 | G14: 8695.006 | H14: 122954.13 | I14: 327919.3 | J14: 450873.43 | K14: 328034.26 | L14: 66935.474 | N14: 8695.006 | O14: 614673.64 | P14: 42048.416 | Q14: 656722.06 | S14: 8695.006 | T14: 68970.356 | V14: 8695.006 | W14: 117385.24
... B30: ... | G30: 8711.006 | H30: 123023.25 | I30: 329050.43 | J30: 452073.68 | K30: 329165.39 | L30: 66954.355 | N30: 8711.006 | O30: 616178.65 | P30: 42125.782 | Q30: 658304.44 | S30: 8711.006 | T30: 68986.948 | V30: 8711.006 | W30: 117800.83
G31: 8712.006 | H31: 123023.25 | I31: 329093.51 | J31: 452116.76 | K31: 329208.47 | L31: 66954.355 | N31: 8712.006 | O31: 616225.35 | P31: 42130.617 | Q31: 658355.97 | S31: 8712.006 | T31: 68986.948 | V31: 8712.006 | W31: 117807.59
G32: 8713.006 | H32: 123023.25 | I32: 329128.68 | J32: 452151.93 | K32: 329243.64 | L32: 66954.355 | N32: 8713.006 | O32: 616263.05 | P32: 42135.453 | Q32: 658398.51 | S32: 8713.006 | T32: 68986.948 | V32: 8713.006 | W32: 117812.56
G33: 8714.006 | H33: 123023.25 | I33: 329162.55 | J33: 452185.8 | K33: 329277.51 | L33: 66954.355 | N33: 8714.006 | O33: 616299.08 | P33: 42140.288 | Q33: 658439.37 | S33: 8714.006 | T33: 68986.948 | V33: 8714.006 | W33: 117817.52
G34: 8715.006 | H34: 123023.25 | I34: 329194.18 | J34: 452217.43 | K34: 329309.14 | L34: 66954.355 | N34: 8715.006 | O34: 616331.88 | P34: 42145.124 | Q34: 658477.01 | S34: 8715.006 | T34: 68986.948 | V34: 8715.006 | W34: 117822.65
G35: 8716.006 | H35: 123023.25 | I35: 329225.23 | J35: 452248.48 | K35: 329340.19 | L35: 66954.355 | N35: 8716.006 | O35: 616364.36 | P35: 42149.959 | Q35: 658514.32 | S35: 8716.006 | T35: 68986.948 | V35: 8716.006 | W35: 117827.06
G36: 8717.006 | H36: 123023.25 | I36: 329258.74 | J36: 452281.99 | K36: 329373.75 | L36: 66954.355 | N36: 8717.006 | O36: 616400.18 | P36: 42154.794 | Q36: 658554.98 | S36: 8717.006 | T36: 68986.948 | V36: 8717.006 | W36: 117831.61
G37: 8718.006 | H37: 123023.25 | I37: 329299.76 | J37: 452323.01 | K37: 329414.77 | L37: 66954.355 | N37: 8718.006 | O37: 616444.43 | P37: 42159.63 | Q37: 658604.06 | S37: 8718.006 | T37: 68986.948 | V37: 8718.006 | W37: 117837.76
G38: 8719.006 | H38: 123023.25 | I38: 329347.1 | J38: 452370.35 | K38: 329462.19 | L38: 66954.355 | N38: 8719.006 | O38: 616495.51 | P38: 42164.465 | Q38: 658659.98 | S38: 8719.006 | T38: 68986.948 | V38: 8719.006 | W38: 117846.46
G39: 8720.006 | H39: 123023.25 | I39: 329408.2 | J39: 452431.46 | K39: 329523.3 | L39: 66954.355 | N39: 8720.006 | O39: 616561.7 | P39: 42169.3 | Q39: 658731 | S39: 8720.006 | T39: 68986.948 | V39: 8720.006 | W39: 117859.3
G40: 8721.006 | H40: 123023.88 | I40: 329474.48 | J40: 452498.36 | K40: 329589.57 | L40: 66954.355 | N40: 8721.006 | O40: 616634.08 | P40: 42174.136 | Q40: 658808.22 | S40: 8721.006 | T40: 68986.948 | V40: 8721.006 | W40: 117873.13
G41: 8722.006 | H41: 123026.32 | I41: 329535.24 | J41: 452561.57 | K41: 329650.33 | L41: 66954.373 | N41: 8722.006 | O41: 616700.45 | P41: 42178.971 | Q41: 658879.42 | S41: 8722.006 | T41: 68986.96 | V41: 8722.006 | W41: 117885.54
G42: 8723.006 | H42: 123030.3 | I42: 329595.43 | J42: 452625.73 | K42: 329710.52 | L42: 66954.431 | N42: 8723.006 | O42: 616766.22 | P42: 42183.807 | Q42: 658950.03 | S42: 8723.006 | T42: 68986.998 | V42: 8723.006 | W42: 117898.12
... G102: 8783.006 | H102: 123103.19 | I102: 333642 | J102: 456745.19 | K102: 333757.34 | L102: 66955.897 | N102: 8783.006 | O102: 621452.62 | P102: 42473.929 | Q102: 663926.55 | S102: 8783.006 | T102: 68988.081 | V102: 8783.006 | W102: 118920.28

Sheet Scenario 2 -20%
H2: Cumulative solar production [kWh] | I2: Cumulative electricity purchased [kWh] | J2: Cumulative electricity consumption [kWh] | K2: Cumulative electricity from grid [kWh] | L2: Cumulative electricity Peer-to-Peer [kWh] | O2: Cumulative bill supplier [DKK] | P2: Cumulative PV cost [DKK] | Q2: Cumulative total costs [DKK] | T2: Cumulative revenue [DKK] | W2: Cumulative CO2 emissions [kg]
G3: 8660.006 | H3: 98341.485 | I3: 350487.93 | J3: 448829.42 | K3: 350605.94 | L3: 55391.725 | N3: 8660.006 | O3: 641725.06 | P3: 41879.178 | Q3: 683604.24 | S3: 8660.006 | T3: 54668.867 | V3: 8660.006 | W3: 124713.9
G4: 8661.006 | H4: 98341.485 | I4: 350568 | J4: 448909.49 | K4: 350686.01 | L4: 55391.725 | N4: 8661.006 | O4: 641801.04 | P4: 41884.013 | Q4: 683685.05 | S4: 8661.006 | T4: 54668.867 | V4: 8661.006 | W4: 124734.33
G5: 8662.006 | H5: 98341.485 | I5: 350633.28 | J5: 448974.77 | K5: 350751.29 | L5: 55391.725 | N5: 8662.006 | O5: 641856.22 | P5: 41888.849 | Q5: 683745.07 | S5: 8662.006 | T5: 54668.867 | V5: 8662.006 | W5: 124749.69
G6: 8663.006 | H6: 98341.485 | I6: 350689.24 | J6: 449030.73 | K6: 350807.25 | L6: 55391.725 | N6: 8663.006 | O6: 641900.34 | P6: 41893.684 | Q6: 683794.03 | S6: 8663.006 | T6: 54668.867 | V6: 8663.006 | W6: 124758.99
G7: 8664.006 | H7: 98341.485 | I7: 350739.54 | J7: 449081.03 | K7: 350857.55 | L7: 55391.725 | N7: 8664.006 | O7: 641940.12 | P7: 41898.519 | Q7: 683838.64 | S7: 8664.006 | T7: 54668.867 | V7: 8664.006 | W7: 124766.87
G8: 8665.006 | H8: 98341.485 | I8: 350776.54 | J8: 449118.03 | K8: 350894.55 | L8: 55391.725 | N8: 8665.006 | O8: 641963.99 | P8: 41903.355 | Q8: 683867.35 | S8: 8665.006 | T8: 54668.867 | V8: 8665.006 | W8: 124772.06
G9: 8666.006 | H9: 98341.485 | I9: 350808.65 | J9: 449150.14 | K9: 350926.66 | L9: 55391.725 | N9: 8666.006 | O9: 641981.46 | P9: 41908.19 | Q9: 683889.65 | S9: 8666.006 | T9: 54668.867 | V9: 8666.006 | W9: 124775.8
G10: 8667.006 | H10: 98341.485 | I10: 350838.37 | J10: 449179.86 | K10: 350956.38 | L10: 55391.725 | N10: 8667.006 | O10: 641995.4 | P10: 41913.026 | Q10: 683908.43 | S10: 8667.006 | T10: 54668.867 | V10: 8667.006 | W10: 124778.88
G11: 8668.006 | H11: 98341.485 | I11: 350867.25 | J11: 449208.74 | K11: 350985.31 | L11: 55391.725 | N11: 8668.006 | O11: 642002.87 | P11: 41917.861 | Q11: 683920.73 | S11: 8668.006 | T11: 54668.867 | V11: 8668.006 | W11: 124781.9
G12: 8669.006 | H12: 98341.485 | I12: 350896.37 | J12: 449237.86 | K12: 351014.43 | L12: 55391.725 | N12: 8669.006 | O12: 642003.11 | P12: 41922.696 | Q12: 683925.8 | S12: 8669.006 | T12: 54668.867 | V12: 8669.006 | W12: 124784.88
G13: 8670.006 | H13: 98341.485 | I13: 350930.63 | J13: 449272.12 | K13: 351048.69 | L13: 55391.725 | N13: 8670.006 | O13: 642003.21 | P13: 41927.532 | Q13: 683930.74 | S13: 8670.006 | T13: 54668.867 | V13: 8670.006 | W13: 124788.54
G14: 8671.006 | H14: 98341.485 | I14: 350972.13 | J14: 449313.62 | K14: 351090.19 | L14: 55391.725 | N14: 8671.006 | O14: 642003.55 | P14: 41932.367 | Q14: 683935.92 | S14: 8671.006 | T14: 54668.867 | V14: 8671.006 | W14: 124793.11
... G102: 8759.006 | H102: 98463.982 | I102: 356616 | J102: 455079.99 | K102: 356734.44 | L102: 55403.952 | N102: 8759.006 | O102: 648547.87 | P102: 42357.88 | Q102: 690905.75 | S102: 8759.006 | T102: 54679.593 | V102: 8759.006 | W102: 126191.78

Sheet Scenario 2 +20%
H3: Cumulative solar production [kWh] | I3: Cumulative electricity purchased [kWh] | J3: Cumulative electricity consumption [kWh] | K3: Cumulative electricity from grid [kWh] | L3: Cumulative electricity Peer-to-Peer [kWh] | O3: Cumulative bill supplier [DKK] | P3: Cumulative PV cost [DKK] | Q3: Cumulative total costs [DKK] | T3: Cumulative revenue [DKK] | W3: Cumulative CO2 emissions [kg]
G4: 8660.006 | H4: 147512.23 | I4: 301317.19 | J4: 448829.42 | K4: 301429.21 | L4: 19.155198 | N4: 8660.006 | O4: 587635.21 | P4: 41879.178 | Q4: 629514.39 | S4: 8660.006 | T4: 82382.919 | V4: 8660.006 | W4: 109207.04
G5: 8661.006 | H5: 147512.23 | I5: 301397.26 | J5: 448909.49 | K5: 301509.28 | L5: 19.155198 | N5: 8661.006 | O5: 587711.19 | P5: 41884.013 | Q5: 629595.2 | S5: 8661.006 | T5: 82382.919 | V5: 8661.006 | W5: 109227.47
G6: 8662.006 | H6: 147512.23 | I6: 301462.54 | J6: 448974.77 | K6: 301574.56 | L6: 19.155198 | N6: 8662.006 | O6: 587766.36 | P6: 41888.849 | Q6: 629655.21 | S6: 8662.006 | T6: 82382.919 | V6: 8662.006 | W6: 109242.84
G7: 8663.006 | H7: 147512.23 | I7: 301518.5 | J7: 449030.73 | K7: 301630.52 | L7: 19.155198 | N7: 8663.006 | O7: 587810.49 | P7: 41893.684 | Q7: 629704.17 | S7: 8663.006 | T7: 82382.919 | V7: 8663.006 | W7: 109252.13
G8: 8664.006 | H8: 147512.23 | I8: 301568.8 | J8: 449081.03 | K8: 301680.82 | L8: 19.155198 | N8: 8664.006 | O8: 587850.26 | P8: 41898.519 | Q8: 629748.78 | S8: 8664.006 | T8: 82382.919 | V8: 8664.006 | W8: 109260.02
G9: 8665.006 | H9: 147512.23 | I9: 301605.8 | J9: 449118.03 | K9: 301717.82 | L9: 19.155198 | N9: 8665.006 | O9: 587874.14 | P9: 41903.355 | Q9: 629777.5 | S9: 8665.006 | T9: 82382.919 | V9: 8665.006 | W9: 109265.21
G10: 8666.006 | H10: 147512.23 | I10: 301637.91 | J10: 449150.14 | K10: 301749.93 | L10: 19.155198 | N10: 8666.006 | O10: 587891.6 | P10: 41908.19 | Q10: 629799.79 | S10: 8666.006 | T10: 82382.919 | V10: 8666.006 | W10: 109268.95
G11: 8667.006 | H11: 147512.23 | I11: 301667.63 | J11: 449179.86 | K11: 301779.65 | L11: 19.155198 | N11: 8667.006 | O11: 587905.55 | P11: 41913.026 | Q11: 629818.57 | S11: 8667.006 | T11: 82382.919 | V11: 8667.006 | W11: 109272.03
G12: 8668.006 | H12: 147512.23 | I12: 301696.51 | J12: 449208.74 | K12: 301808.58 | L12: 19.155198 | N12: 8668.006 | O12: 587913.02 | P12: 41917.861 | Q12: 629830.88 | S12: 8668.006 | T12: 82382.919 | V12: 8668.006 | W12: 109275.05
G13: 8669.006 | H13: 147512.23 | I13: 301725.63 | J13: 449237.86 | K13: 301837.7 | L13: 19.155198 | N13: 8669.006 | O13: 587913.25 | P13: 41922.696 | Q13: 629835.95 | S13: 8669.006 | T13: 82382.919 | V13: 8669.006 | W13: 109278.03
G14: 8670.006 | H14: 147512.23 | I14: 301759.89 | J14: 449272.12 | K14: 301871.96 | L14: 19.155198 | N14: 8670.006 | O14: 587913.36 | P14: 41927.532 | Q14: 629840.89 | S14: 8670.006 | T14: 82382.919 | V14: 8670.006 | W14: 109281.68
G15: 8671.006 | H15: 147512.23 | I15: 301801.39 | J15: 449313.62 | K15: 301913.46 | L15: 19.155198 | N15: 8671.006 | O15: 587913.7 | P15: 41932.367 | Q15: 629846.06 | S15: 8671.006 | T15: 82382.919 | V15: 8671.006 | W15: 109286.26
... G103: 8759.006 | H103: 147695.97 | I103: 307384.01 | J103: 455079.99 | K103: 307496.47 | L103: 19.155209 | N103: 8759.006 | O103: 594378.76 | P103: 42357.88 | Q103: 636736.64 | S103: 8759.006 | T103: 82408.203 | V103: 8759.006 | W103: 110661.74

Sheet Scenario 3
H2: Cumulative solar production [kWh] | I2: Cumulative electricity purchased [kWh] | J2: Cumulative electricity consumption [kWh] | K2: Cumulative electricity from grid [kWh] | L2: Cumulative electricity Peer-to-Peer [kWh] | O2: Cumulative bill supplier [DKK] | P2: Cumulative PV cost [DKK] | Q2: Cumulative total costs [DKK] | T2: Cumulative revenue [DKK] | X2: Cumulative CO2 emissions [kg]
G3: 8684.006 | H3: 531595.79 | I3: -81209.349 | J3: 450386.45 | K3: -81157.492 | L3: 4527.1776 | N3: 8684.006 | O3: 351713.44 | P3: 181567.6 | Q3: 533281.04 | S3: 8684.006 | T3: 147807.13 | W3: 8684.006 | X3: -11641.075
G4: 8685.006 | H4: 531595.79 | I4: -81133.759 | J4: 450462.04 | K4: -81081.902 | L4: 4527.1776 | N4: 8685.006 | O4: 351795.09 | P4: 181588.5 | Q4: 533383.6 | S4: 8685.006 | T4: 147807.13 | W4: 8685.006 | X4: -11627.408
G5: 8686.006 | H5: 531595.79 | I5: -81069.729 | J5: 450526.07 | K5: -81017.872 | L5: 4527.1776 | N5: 8686.006 | O5: 351861.97 | P5: 181609.41 | Q5: 533471.38 | S5: 8686.006 | T5: 147807.13 | W5: 8686.006 | X5: -11615.868
G6: 8687.006 | H6: 531595.79 | I6: -81018.549 | J6: 450577.25 | K6: -80966.502 | L6: 4527.1776 | N6: 8687.006 | O6: 351914.89 | P6: 181630.32 | Q6: 533545.21 | S6: 8687.006 | T6: 147807.13 | W6: 8687.006 | X6: -11603.651
G7: 8688.006 | H7: 531595.79 | I7: -80976.409 | J7: 450619.39 | K7: -80924.362 | L7: 4527.1776 | N7: 8688.006 | O7: 351963.36 | P7: 181651.22 | Q7: 533614.59 | S7: 8688.006 | T7: 147807.13 | W7: 8688.006 | X7: -11590.474
G8: 8689.006 | H8: 531595.79 | I8: -80939.639 | J8: 450656.16 | K8: -80887.592 | L8: 4527.1776 | N8: 8689.006 | O8: 352005.63 | P8: 181672.13 | Q8: 533677.76 | S8: 8689.006 | T8: 147807.13 | W8: 8689.006 | X8: -11578.527
G9: 8690.006 | H9: 531595.79 | I9: -80906.489 | J9: 450689.31 | K9: -80854.442 | L9: 4527.1776 | N9: 8690.006 | O9: 352043.94 | P9: 181693.03 | Q9: 533736.98 | S9: 8690.006 | T9: 147807.13 | W9: 8690.006 | X9: -11567.545
G10: 8691.006 | H10: 531595.79 | I10: -80874.689 | J10: 450721.11 | K10: -80822.642 | L10: 4527.1776 | N10: 8691.006 | O10: 352081.02 | P10: 181713.94 | Q10: 533794.96 | S10: 8691.006 | T10: 147807.13 | W10: 8691.006 | X10: -11555.393
G11: 8692.006 | H11: 531595.79 | I11: -80844.749 | J11: 450751.05 | K11: -80792.702 | L11: 4527.1776 | N11: 8692.006 | O11: 352118.03 | P11: 181734.85 | Q11: 533852.88 | S11: 8692.006 | T11: 147807.13 | W11: 8692.006 | X11: -11542.367
G12: 8693.006 | H12: 531595.79 | I12: -80812.889 | J12: 450782.91 | K12: -80760.842 | L12: 4527.1776 | N12: 8693.006 | O12: 352160.1 | P12: 181755.75 | Q12: 533915.85 | S12: 8693.006 | T12: 147807.13 | W12: 8693.006 | X12: -11527.864
G13: 8694.006 | H13: 531595.79 | I13: -80771.009 | J13: 450824.79 | K13: -80718.962 | L13: 4527.1776 | N13: 8694.006 | O13: 352217.24 | P13: 181776.66 | Q13: 533993.9 | S13: 8694.006 | T13: 147807.13 | W13: 8694.006 | X13: -11506.378
G14: 8695.006 | H14: 531595.79 | I14: -80722.369 | J14: 450873.43 | K14: -80670.322 | L14: 4527.1776 | N14: 8695.006 | O14: 352289.41 | P14: 181797.56 | Q14: 534086.98 | S14: 8695.006 | T14: 147807.13 | W14: 8695.006 | X14: -11477.376
... G18: 8699.006 | H18: 531742.52 | I18: -80612.642 | J18: 451129.88 | K18: -80560.595 | L18: 4533.7526 | N18: 8699.006 | O18: 352485 | P18: 181881.19 | Q18: 534366.19 | S18: 8699.006 | T18: 147840.3 | W18: 8699.006 | X18: -11406.802
B19: Objects: | G19: 8700.006 | H19: 531817.33 | I19: -80626.546 | J19: 451190.79 | K19: -80574.499 | L19: 4535.7416 | N19: 8700.006 | O19: 352480.75 | P19: 181902.09 | Q19: 534382.84 | S19: 8700.006 | T19: 147855.09 | W19: 8700.006 | X19: -11415.122
B20: 0: root.community.consumers[0] | G20: 8701.006 | H20: 531869.78 | I20: -80618.497 | J20: 451251.29 | K20: -80566.45 | L20: 4537.9216 | N20: 8701.006 | O20: 352492.58 | P20: 181923 | Q20: 534415.58 | S20: 8701.006 | T20: 147864.93 | W20: 8701.006 | X20: -11410.759
B21: 1: root.community.consumers[1] | G21: 8702.006 | H21: 531892.54 | I21: -80579.744 | J21: 451312.8 | K21: -80527.697 | L21: 4538.2016 | N21: 8702.006 | O21: 352547.42 | P21: 181943.9 | Q21: 534491.33 | S21: 8702.006 | T21: 147865.5 | W21: 8702.006 | X21: -11392.414
B22: 2: root.community.consumers[2] | G22: 8703.006 | H22: 531894.61 | I22: -80515.188 | J22: 451379.43 | K22: -80463.141 | L22: 4538.2016 | N22: 8703.006 | O22: 352637.96 | P22: 181964.81 | Q22: 534602.77 | S22: 8703.006 | T22: 147865.5 | W22: 8703.006 | X22: -11366.736
B23: 3: root.community.consumers[3] | G23: 8704.006 | H23: 531894.62 | I23: -80429.966 | J23: 451464.66 | K23: -80377.919 | L23: 4538.2016 | N23: 8704.006 | O23: 352760.22 | P23: 181985.72 | Q23: 534745.94 | S23: 8704.006 | T23: 147865.5 | W23: 8704.006 | X23: -11337.372
B24: 4: root.community.consumers[4] | G24: 8705.006 | H24: 531894.62 | I24: -80319.256 | J24: 451575.37 | K24: -80267.209 | L24: 4538.2016 | N24: 8705.006 | O24: 352914.58 | P24: 182006.62 | Q24: 534921.2 | S24: 8705.006 | T24: 147865.5 | W24: 8705.006 | X24: -11302.085
B25: 5: root.community.consumers[5] | G25: 8706.006 | H25: 531894.62 | I25: -80201.416 | J25: 451693.21 | K25: -80149.369 | L25: 4538.2016 | N25: 8706.006 | O25: 353073.34 | P25: 182027.53 | Q25: 535100.87 | S25: 8706.006 | T25: 147865.5 | W25: 8706.006 | X25: -11271.078
B26: 6: root.community.consumers[6] | G26: 8707.006 | H26: 531894.62 | I26: -80105.336 | J26: 451789.29 | K26: -80053.289 | L26: 4538.2016 | N26: 8707.006 | O26: 353191.18 | P26: 182048.43 | Q26: 535239.61 | S26: 8707.006 | T26: 147865.5 | W26: 8707.006 | X26: -11249.385
B27: 7: root.community.consumers[7] | G27: 8708.006 | H27: 531894.62 | I27: -80016.086 | J27: 451878.54 | K27: -79964.039 | L27: 4538.2016 | N27: 8708.006 | O27: 353277.2 | P27: 182069.34 | Q27: 535346.54 | S27: 8708.006 | T27: 147865.5 | W27: 8708.006 | X27: -11232.426
B28: 8: root.community.consumers[8] | G28: 8709.006 | H28: 531894.62 | I28: -79943.116 | J28: 451951.51 | K28: -79891.069 | L28: 4538.2016 | N28: 8709.006 | O28: 353346.22 | P28: 182090.25 | Q28: 535436.47 | S28: 8709.006 | T28: 147865.5 | W28: 8709.006 | X28: -11219.02
B29: 9: root.community.consumers[9] | G29: 8710.006 | H29: 531894.62 | I29: -79876.256 | J29: 452018.37 | K29: -79824.209 | L29: 4538.2016 | N29: 8710.006 | O29: 353407.62 | P29: 182111.15 | Q29: 535518.77 | S29: 8710.006 | T29: 147865.5 | W29: 8710.006 | X29: -11207.747
B30: ... | G30: 8711.006 | H30: 531894.62 | I30: -79820.946 | J30: 452073.68 | K30: -79768.899 | L30: 4538.2016 | N30: 8711.006 | O30: 353456.35 | P30: 182132.06 | Q30: 535588.41 | S30: 8711.006 | T30: 147865.5 | W30: 8711.006 | X30: -11198.815
G31: 8712.006 | H31: 531894.62 | I31: -79777.866 | J31: 452116.76 | K31: -79725.819 | L31: 4538.2016 | N31: 8712.006 | O31: 353503.05 | P31: 182152.96 | Q31: 535656.01 | S31: 8712.006 | T31: 147865.5 | W31: 8712.006 | X31: -11192.051
G32: 8713.006 | H32: 531894.62 | I32: -79742.696 | J32: 452151.93 | K32: -79690.649 | L32: 4538.2016 | N32: 8713.006 | O32: 353540.75 | P32: 182173.87 | Q32: 535714.62 | S32: 8713.006 | T32: 147865.5 | W32: 8713.006 | X32: -11187.082
G33: 8714.006 | H33: 531894.62 | I33: -79708.826 | J33: 452185.8 | K33: -79656.779 | L33: 4538.2016 | N33: 8714.006 | O33: 353576.78 | P33: 182194.78 | Q33: 535771.56 | S33: 8714.006 | T33: 147865.5 | W33: 8714.006 | X33: -11182.123
G34: 8715.006 | H34: 531894.62 | I34: -79677.196 | J34: 452217.43 | K34: -79625.149 | L34: 4538.2016 | N34: 8715.006 | O34: 353609.58 | P34: 182215.68 | Q34: 535825.26 | S34: 8715.006 | T34: 147865.5 | W34: 8715.006 | X34: -11176.989
G35: 8716.006 | H35: 531894.62 | I35: -79646.146 | J35: 452248.48 | K35: -79594.099 | L35: 4538.2016 | N35: 8716.006 | O35: 353642.05 | P35: 182236.59 | Q35: 535878.64 | S35: 8716.006 | T35: 147865.5 | W35: 8716.006 | X35: -11172.586
G36: 8717.006 | H36: 531894.62 | I36: -79612.636 | J36: 452281.99 | K36: -79560.539 | L36: 4538.2016 | N36: 8717.006 | O36: 353677.88 | P36: 182257.49 | Q36: 535935.37 | S36: 8717.006 | T36: 147865.5 | W36: 8717.006 | X36: -11168.031
G37: 8718.006 | H37: 531894.62 | I37: -79571.616 | J37: 452323.01 | K37: -79519.519 | L37: 4538.2016 | N37: 8718.006 | O37: 353722.13 | P37: 182278.4 | Q37: 536000.53 | S37: 8718.006 | T37: 147865.5 | W37: 8718.006 | X37: -11161.884
G38: 8719.006 | H38: 531894.62 | I38: -79524.276 | J38: 452370.35 | K38: -79472.099 | L38: 4538.2016 | N38: 8719.006 | O38: 353773.21 | P38: 182299.3 | Q38: 536072.52 | S38: 8719.006 | T38: 147865.5 | W38: 8719.006 | X38: -11153.178
G39: 8720.006 | H39: 531894.65 | I39: -79463.191 | J39: 452431.46 | K39: -79411.014 | L39: 4538.2016 | N39: 8720.006 | O39: 353839.38 | P39: 182320.21 | Q39: 536159.59 | S39: 8720.006 | T39: 147865.5 | W39: 8720.006 | X39: -11140.35
G40: 8721.006 | H40: 531897.35 | I40: -79398.997 | J40: 452498.36 | K40: -79346.82 | L40: 4538.2016 | N40: 8721.006 | O40: 353909.49 | P40: 182341.12 | Q40: 536250.6 | S40: 8721.006 | T40: 147865.5 | W40: 8721.006 | X40: -11126.955
G41: 8722.006 | H41: 531907.93 | I41: -79346.36 | J41: 452561.57 | K41: -79294.183 | L41: 4538.1986 | N41: 8722.006 | O41: 353966.97 | P41: 182362.02 | Q41: 536329 | S41: 8722.006 | T41: 147865.53 | W41: 8722.006 | X41: -11116.199
G42: 8723.006 | H42: 531925.11 | I42: -79299.387 | J42: 452625.73 | K42: -79247.21 | L42: 4538.2086 | N42: 8723.006 | O42: 354018.31 | P42: 182382.93 | Q42: 536401.24 | S42: 8723.006 | T42: 147865.64 | W42: 8723.006 | X42: -11106.386
... G102: 8783.006 | H102: 532240.26 | I102: -75495.078 | J102: 456745.19 | K102: -75442.681 | L102: 4538.2396 | N102: 8783.006 | O102: 358415.21 | P102: 183637.28 | Q102: 542052.49 | S102: 8783.006 | T102: 147869.8 | W102: 8783.006 | X102: -10137.416

Sheet Scenario 3 -20%
H2: Cumulative solar production [kWh] | I2: Cumulative electricity purchased [kWh] | J2: Cumulative electricity consumption [kWh] | K2: Cumulative electricity from grid [kWh] | L2: Cumulative electricity Peer-to-Peer [kWh] | O2: Cumulative bill supplier [DKK] | P2: Cumulative PV cost [DKK] | Q2: Cumulative total costs [DKK] | T2: Cumulative revenue [DKK] | W2: Cumulative CO2 emissions [kg]
G3: 8660.006 | H3: 425182.3 | I3: 23647.114 | J3: 448829.42 | K3: 23698.747 | L3: -0.079973719 | N3: 8660.006 | O3: 403354.09 | P3: 181065.86 | Q3: 584419.94 | S3: 8660.006 | T3: 113196.39 | V3: 8660.006 | W3: 21632.015
G4: 8661.006 | H4: 425182.3 | I4: 23727.184 | J4: 448909.49 | K4: 23778.817 | L4: -0.079973719 | N4: 8661.006 | O4: 403430.07 | P4: 181086.76 | Q4: 584516.83 | S4: 8661.006 | T4: 113196.39 | V4: 8661.006 | W4: 21652.446
G5: 8662.006 | H5: 425182.3 | I5: 23792.464 | J5: 448974.77 | K5: 23844.097 | L5: -0.079973719 | N5: 8662.006 | O5: 403485.24 | P5: 181107.67 | Q5: 584592.91 | S5: 8662.006 | T5: 113196.39 | V5: 8662.006 | W5: 21667.809
G6: 8663.006 | H6: 425182.3 | I6: 23848.424 | J6: 449030.73 | K6: 23900.057 | L6: -0.079973719 | N6: 8663.006 | O6: 403529.37 | P6: 181128.58 | Q6: 584657.94 | S6: 8663.006 | T6: 113196.39 | V6: 8663.006 | W6: 21677.107
G7: 8664.006 | H7: 425182.3 | I7: 23898.724 | J7: 449081.03 | K7: 23950.357 | L7: -0.079973719 | N7: 8664.006 | O7: 403569.14 | P7: 181149.48 | Q7: 584718.62 | S7: 8664.006 | T7: 113196.39 | V7: 8664.006 | W7: 21684.988
G8: 8665.006 | H8: 425182.3 | I8: 23935.724 | J8: 449118.03 | K8: 23987.357 | L8: -0.079973719 | N8: 8665.006 | O8: 403593.02 | P8: 181170.39 | Q8: 584763.41 | S8: 8665.006 | T8: 113196.39 | V8: 8665.006 | W8: 21690.179
G9: 8666.006 | H9: 425182.3 | I9: 23967.834 | J9: 449150.14 | K9: 24019.467 | L9: -0.079973719 | N9: 8666.006 | O9: 403610.48 | P9: 181191.29 | Q9: 584801.77 | S9: 8666.006 | T9: 113196.39 | V9: 8666.006 | W9: 21693.918
G10: 8667.006 | H10: 425182.3 | I10: 23997.554 | J10: 449179.86 | K10: 24049.187 | L10: -0.079973719 | N10: 8667.006 | O10: 403624.43 | P10: 181212.2 | Q10: 584836.63 | S10: 8667.006 | T10: 113196.39 | V10: 8667.006 | W10: 21697.002
G11: 8668.006 | H11: 425182.3 | I11: 24026.434 | J11: 449208.74 | K11: 24078.117 | L11: -0.079973719 | N11: 8668.006 | O11: 403631.89 | P11: 181233.1 | Q11: 584865 | S11: 8668.006 | T11: 113196.39 | V11: 8668.006 | W11: 21700.02
G12: 8669.006 | H12: 425182.3 | I12: 24055.554 | J12: 449237.86 | K12: 24107.237 | L12: -0.079973719 | N12: 8669.006 | O12: 403632.13 | P12: 181254.01 | Q12: 584886.14 | S12: 8669.006 | T12: 113196.39 | V12: 8669.006 | W12: 21703.001
G13: 8670.006 | H13: 425182.3 | I13: 24089.814 | J13: 449272.12 | K13: 24141.497 | L13: -0.079973719 | N13: 8670.006 | O13: 403632.23 | P13: 181274.92 | Q13: 584907.15 | S13: 8670.006 | T13: 113196.39 | V13: 8670.006 | W13: 21706.657
G14: 8671.006 | H14: 425182.3 | I14: 24131.314 | J14: 449313.62 | K14: 24182.997 | L14: -0.079973719 | N14: 8671.006 | O14: 403632.58 | P14: 181295.82 | Q14: 584928.4 | S14: 8671.006 | T14: 113196.39 | V14: 8671.006 | W14: 21711.228
... G102: 8759.006 | H102: 425711.92 | I102: 29368.063 | J102: 455079.99 | K102: 29420.096 | L102: -0.079973719 | N102: 8759.006 | O102: 409650.02 | P102: 183135.54 | Q102: 592785.56 | S102: 8759.006 | T102: 113238.99 | V102: 8759.006 | W102: 22955.771

Sheet Scenario 3 +20%
H3: Cumulative solar production [kWh] | I3: Cumulative electricity purchased [kWh] | J3: Cumulative electricity consumption [kWh] | K3: Cumulative electricity from grid [kWh] | L3: Cumulative electricity Peer-to-Peer [kWh] | O3: Cumulative bill supplier [DKK] | P3: Cumulative PV cost [DKK] | Q3: Cumulative total costs [DKK] | T3: Cumulative revenue [DKK] | W3: Cumulative CO2 emissions [kg]
G4: 8660.006 | H4: 637773.45 | I4: -188944.04 | J4: 448829.42 | K4: -188892.52 | L4: -0.25197543 | N4: 8660.006 | O4: 300948.93 | P4: 181065.86 | Q4: 482014.79 | S4: 8660.006 | T4: 183415.1 | V4: 8660.006 | W4: -45401.887
G5: 8661.006 | H5: 637773.45 | I5: -188863.97 | J5: 448909.49 | K5: -188812.45 | L5: -0.25197543 | N5: 8661.006 | O5: 301024.91 | P5: 181086.76 | Q5: 482111.68 | S5: 8661.006 | T5: 183415.1 | V5: 8661.006 | W5: -45381.456
G6: 8662.006 | H6: 637773.45 | I6: -188798.69 | J6: 448974.77 | K6: -188747.17 | L6: -0.25197543 | N6: 8662.006 | O6: 301080.09 | P6: 181107.67 | Q6: 482187.76 | S6: 8662.006 | T6: 183415.1 | V6: 8662.006 | W6: -45366.093
G7: 8663.006 | H7: 637773.45 | I7: -188742.73 | J7: 449030.73 | K7: -188691.21 | L7: -0.25197543 | N7: 8663.006 | O7: 301124.21 | P7: 181128.58 | Q7: 482252.79 | S7: 8663.006 | T7: 183415.1 | V7: 8663.006 | W7: -45356.795
G8: 8664.006 | H8: 637773.45 | I8: -188692.43 | J8: 449081.03 | K8: -188640.91 | L8: -0.25197543 | N8: 8664.006 | O8: 301163.99 | P8: 181149.48 | Q8: 482313.47 | S8: 8664.006 | T8: 183415.1 | V8: 8664.006 | W8: -45348.914
G9: 8665.006 | H9: 637773.45 | I9: -188655.43 | J9: 449118.03 | K9: -188603.91 | L9: -0.25197543 | N9: 8665.006 | O9: 301187.87 | P9: 181170.39 | Q9: 482358.25 | S9: 8665.006 | T9: 183415.1 | V9: 8665.006 | W9: -45343.723
G10: 8666.006 | H10: 637773.45 | I10: -188623.32 | J10: 449150.14 | K10: -188571.8 | L10: -0.25197543 | N10: 8666.006 | O10: 301205.33 | P10: 181191.29 | Q10: 482396.62 | S10: 8666.006 | T10: 183415.1 | V10: 8666.006 | W10: -45339.984
G11: 8667.006 | H11: 637773.45 | I11: -188593.6 | J11: 449179.86 | K11: -188542.08 | L11: -0.25197543 | N11: 8667.006 | O11: 301219.27 | P11: 181212.2 | Q11: 482431.47 | S11: 8667.006 | T11: 183415.1 | V11: 8667.006 | W11: -45336.9
G12: 8668.006 | H12: 637773.45 | I12: -188564.72 | J12: 449208.74 | K12: -188513.15 | L12: -0.25197543 | N12: 8668.006 | O12: 301226.74 | P12: 181233.1 | Q12: 482459.85 | S12: 8668.006 | T12: 183415.1 | V12: 8668.006 | W12: -45333.882
G13: 8669.006 | H13: 637773.45 | I13: -188535.6 | J13: 449237.86 | K13: -188484.03 | L13: -0.25197543 | N13: 8669.006 | O13: 301226.98 | P13: 181254.01 | Q13: 482480.99 | S13: 8669.006 | T13: 183415.1 | V13: 8669.006 | W13: -45330.901
G14: 8670.006 | H14: 637773.45 | I14: -188501.34 | J14: 449272.12 | K14: -188449.77 | L14: -0.25197543 | N14: 8670.006 | O14: 301227.08 | P14: 181274.92 | Q14: 482502 | S14: 8670.006 | T14: 183415.1 | V14: 8670.006 | W14: -45327.245
